Workbook

Sheet uom_category
A1: code | B1: name | C1: uuid | D1: sync_status | E1: sync_message | F1: sync_time
A2: CA00001 | B2: Count
A3: CA00002 | B3: Weight
A4: CA00003 | B4: Time
A5: CA00004 | B5: Length
A6: CA00005 | B6: Volume
A7: CA00005 | B7: Services
A8: CA00008 | B8: Sachet
A9: CA00010 | B9: Counting
A10: CA00012 | B10: Container
A11: CA00014 | B11: Container
A12: CA00016 | B12: Package
A13: CA00017 | B13: Package
A14: CA00018 | B14: Container
B15: uom_category_name

Sheet uom
A1: code | B1: name | C1: uom_category_code | D1: uom_category_name | E1: factor | F1: rounding | G1: active | H1: uomType | I1: uuid | J1: sync_status | K1: sync_message | L1: sync_time
A2: =concatenate("UM", text(A2, "00000")) | B2: Unit(s) | C2: =XLOOKUP(E2, uom_category!C:C, uom_category!B:B, "Not Found") | D2: Count | E2: 1 | F2: 0.001 | G2: true | H2: reference
A3: =concatenate("UM", text(A3, "00000")) | B3: Dozen(s) | C3: =XLOOKUP(E3, uom_category!C:C, uom_category!B:B, "Not Found") | D3: Count | E3: 0.083333333 | F3: 0.01 | G3: true | H3: bigger
A4: =concatenate("UM", text(A4, "00000")) | B4: kg | C4: =XLOOKUP(E4, uom_category!C:C, uom_category!B:B, "Not Found") | D4: Weight | E4: 1 | F4: 0.001 | G4: true | H4: reference
A5: =concatenate("UM", text(A5, "00000")) | B5: g | C5: =XLOOKUP(E5, uom_category!C:C, uom_category!B:B, "Not Found") | D5: Weight | E5: 1000 | F5: 0.01 | G5: true | H5: smaller
A6: =concatenate("UM", text(A6, "00000")) | B6: Day(s) | C6: =XLOOKUP(E6, uom_category!C:C, uom_category!B:B, "Not Found") | D6: Time | E6: 1 | F6: 0.01 | G6: true | H6: reference
A7: =concatenate("UM", text(A7, "00000")) | B7: Hour(s) | C7: =XLOOKUP(E7, uom_category!C:C, uom_category!B:B, "Not Found") | D7: Time | E7: 8 | F7: 0.01 | G7: true | H7: smaller
A8: =concatenate("UM", text(A8, "00000")) | B8: t | C8: =XLOOKUP(E8, uom_category!C:C, uom_category!B:B, "Not Found") | D8: Weight | E8: 0.001 | F8: 0.01 | G8: true | H8: bigger
A9: =concatenate("UM", text(A9, "00000")) | B9: m | C9: =XLOOKUP(E9, uom_category!C:C, uom_category!B:B, "Not Found") | D9: Length | E9: 1 | F9: 0.01 | G9: true | H9: reference
A10: =concatenate("UM", text(A10, "00000")) | B10: km | C10: =XLOOKUP(E10, uom_category!C:C, uom_category!B:B, "Not Found") | D10: Length | E10: 0.001 | F10: 0.01 | G10: true | H10: bigger
A11: =concatenate("UM", text(A11, "00000")) | B11: cm | C11: =XLOOKUP(E11, uom_category!C:C, uom_category!B:B, "Not Found") | D11: Length | E11: 100 | F11: 0.01 | G11: true | H11: smaller
A12: =concatenate("UM", text(A12, "00000")) | B12: Liter(s) | C12: =XLOOKUP(E12, uom_category!C:C, uom_category!B:B, "Not Found") | D12: Volume | E12: 1 | F12: 0.01 | G12: true | H12: reference
A13: =concatenate("UM", text(A13, "00000")) | B13: lb(s) | C13: =XLOOKUP(E13, uom_category!C:C, uom_category!B:B, "Not Found") | D13: Weight | E13: 2.20462 | F13: 0.01 | G13: true | H13: smaller
... A56: =concatenate("UM", text(A56, "00000")) | B56: Oral Vial | C56: =XLOOKUP(E56, uom_category!C:C, uom_category!B:B, "Not Found") | D56: Container | E56: 1 | F56: 0.01 | G56: true | H56: bigger

Sheet item_category
A1: code | B1: name | C1: parent_code | D1: parentName | E1: uuid | F1: sync_status | G1: sync_message | H1: sync_time
A2: =concatenate("CA", text(A2, "00000")) | B2: Product
A3: =concatenate("CA", text(A3, "00000")) | B3: Service | D3: All
A4: =concatenate("CA", text(A4, "00000")) | B4: Medical | C4: CA00002 | D4: All
A5: =concatenate("CA", text(A5, "00000")) | B5: Expenses | C5: CA00002 | D5: All
A6: =concatenate("CA", text(A6, "00000")) | B6: Internal | D6: All
A7: =concatenate("CA", text(A7, "00000")) | B7: Drug | C7: CA00002 | D7: Saleable
A8: =concatenate("CA", text(A8, "00000")) | B8: Injection | C8: CA00005 | D8: Medical
A9: =concatenate("CA", text(A9, "00000")) | B9: Saleable2 | C9: CA00001 | D9: Services
A10: =concatenate("CA", text(A10, "00000")) | B10: Software | C10: CA00001 | D10: Saleable
A11: =concatenate("CA", text(A11, "00000")) | B11: Office Furniture | C11: CA00076 | D11: Saleable
A12: =concatenate("CA", text(A12, "00000")) | B12: Counting | C12: CA00005 | D12: All
A13: =concatenate("CA", text(A13, "00000")) | B13: Consumable | D13: All
A14: =concatenate("CA", text(A14, "00000")) | B14: PoS | D14: Saleable
A15: =concatenate("CA", text(A15, "00000")) | B15: No Category Yet
A16: =concatenate("CA", text(A16, "00000")) | B16: Counting Pack | C16: CA00002
A17: =concatenate("CA", text(A17, "00000")) | B17: Counting Retail | C17: CA00002
A18: =concatenate("CA", text(A18, "00000")) | B18: Eye&Ear Drops | C18: CA00002
A19: =concatenate("CA", text(A19, "00000")) | B19: Ear Drops | C19: CA00002
A20: =concatenate("CA", text(A20, "00000")) | B20: Eye Drops | C20: CA00002
A21: =concatenate("CA", text(A21, "00000")) | B21: Infusions | C21: CA00002
A22: =concatenate("CA", text(A22, "00000")) | B22: Injections | C22: CA00002
A23: =concatenate("CA", text(A23, "00000")) | B23: Ethical Liquids | C23: CA00002
A24: =concatenate("CA", text(A24, "00000")) | B24: OTC Oral Drops | C24: CA00002
A25: =concatenate("CA", text(A25, "00000")) | B25: Powder | C25: CA00002
A26: =concatenate("CA", text(A26, "00000")) | B26: Surgicals | C26: CA00001
A27: =concatenate("CA", text(A27, "00000")) | B27: Ethical Sachets | C27: CA00002
A28: =concatenate("CA", text(A28, "00000")) | B28: OTC Sachets | C28: CA00002
A29: =concatenate("CA", text(A29, "00000")) | B29: Supermarket
A30: =concatenate("CA", text(A30, "00000")) | B30: Stationary | C30: CA00001
A31: =concatenate("CA", text(A31, "00000")) | B31: Tubes & Creams | C31: CA00005
A32: =concatenate("CA", text(A32, "00000")) | B32: OTC Liquids | C32: CA00005
A33: =concatenate("CA", text(A33, "00000")) | B33: Medical Consultation | C33: CA00002
A34: =concatenate("CA", text(A34, "00000")) | B34: Nose Drops | C34: CA00005
A35: =concatenate("CA", text(A35, "00000")) | B35: Ethical Oral Drops | C35: CA00005
A36: =concatenate("CA", text(A36, "00000")) | B36: Medical Equipments | C36: CA00001
A37: =concatenate("CA", text(A37, "00000")) | B37: item_category_name

Sheet classification
A1: code | B1: name | C1: uuid | D1: sync_status | E1: sync_message | F1: sync_time
A2: =concatenate("CA", text(A2, "00000")) | B2: All
A19: ignore | B19: classification_name

Sheet item
A1: sn | B1: name | C1: code | D1: category_id | E1: category_code | F1: item_category_name | G1: drug_code | H1: drug_name | I1: unit_price | J1: uomCode | K1: uom_name | L1: purchase_uom_code | M1: purchase_uom_name | N1: active | O1: tracking | P1: classification_code | Q1: classification_name | R1: uuid | S1: sync_status | T1: sync_message | U1: sync_time
A2: 1 | B2: Inj Fortwin | C2: =CONCATENATE("PD", TEXT(A2, "1000000")) | D2: 65 | E2: =XLOOKUP(G2, item_category!C:C, item_category!B:B, "Not Found") | F2: Injection | G2: =XLOOKUP(I2, drug!B:B, drug!A:A, "Not Found") | H2: Fortwin | I2: 1 | J2: =XLOOKUP(L2, uom!C:C, uom!B:B, "Not Found") | K2: Injection | L2: =XLOOKUP(N2, uom!C:C, uom!B:B, "Not Found") | M2: Unit(s) | N2: false | O2: none | P2: =XLOOKUP(R2, classification!C:C, classification!B:B, "Not Found") | Q2: All
A3: 2 | B3: 2.2.1 Forte Syrup | C3: =CONCATENATE("PD", TEXT(A3, "1000000")) | D3: 67 | E3: =XLOOKUP(G3, item_category!C:C, item_category!B:B, "Not Found") | F3: OTC Liquids | G3: =XLOOKUP(I3, drug!B:B, drug!A:A, "Not Found") | H3: 2 2 1 Forte Syrup | I3: 1 | J3: =XLOOKUP(L3, uom!C:C, uom!B:B, "Not Found") | K3: Unit(s) | L3: =XLOOKUP(N3, uom!C:C, uom!B:B, "Not Found") | M3: Unit(s) | N3: false | O3: none | P3: =XLOOKUP(R3, classification!C:C, classification!B:B, "Not Found") | Q3: All
A4: 3 | B4: Drawer | C4: =CONCATENATE("PD", TEXT(A4, "1000000")) | D4: 8 | E4: =XLOOKUP(G4, item_category!C:C, item_category!B:B, "Not Found") | F4: Office Furniture | G4: =XLOOKUP(I4, drug!B:B, drug!A:A, "Not Found") | H4: Drawer | I4: 3645 | J4: =XLOOKUP(L4, uom!C:C, uom!B:B, "Not Found") | K4: Unit(s) | L4: =XLOOKUP(N4, uom!C:C, uom!B:B, "Not Found") | M4: Unit(s) | N4: false | O4: none | P4: =XLOOKUP(R4, classification!C:C, classification!B:B, "Not Found") | Q4: All
A5: 4 | B5: Acepol Paracetamol Syrup | C5: =CONCATENATE("PD", TEXT(A5, "1000000")) | D5: 67 | E5: =XLOOKUP(G5, item_category!C:C, item_category!B:B, "Not Found") | F5: OTC Liquids | G5: =XLOOKUP(I5, drug!B:B, drug!A:A, "Not Found") | H5: Paracetamol | I5: 1 | J5: =XLOOKUP(L5, uom!C:C, uom!B:B, "Not Found") | K5: Unit(s) | L5: =XLOOKUP(N5, uom!C:C, uom!B:B, "Not Found") | M5: Unit(s) | N5: false | O5: none | P5: =XLOOKUP(R5, classification!C:C, classification!B:B, "Not Found") | Q5: All
A6: 5 | B6: Digoxin 250mg (X28) | C6: =CONCATENATE("PD", TEXT(A6, "1000000")) | D6: 74 | E6: =XLOOKUP(G6, item_category!C:C, item_category!B:B, "Not Found") | F6: Ethical Sachets | G6: =XLOOKUP(I6, drug!B:B, drug!A:A, "Not Found") | H6: Digoxin | I6: 1 | J6: =XLOOKUP(L6, uom!C:C, uom!B:B, "Not Found") | K6: Unit(s) | L6: =XLOOKUP(N6, uom!C:C, uom!B:B, "Not Found") | M6: Unit(s) | N6: false | O6: none | P6: =XLOOKUP(R6, classification!C:C, classification!B:B, "Not Found") | Q6: All
A7: 6 | B7: Neurogesic Extra Oint 25g | C7: =CONCATENATE("PD", TEXT(A7, "1000000")) | D7: 78 | E7: =XLOOKUP(G7, item_category!C:C, item_category!B:B, "Not Found") | F7: Tubes & Creams | G7: =XLOOKUP(I7, drug!B:B, drug!A:A, "Not Found") | H7: Neurogesic | I7: 450 | J7: =XLOOKUP(L7, uom!C:C, uom!B:B, "Not Found") | K7: Tube | L7: =XLOOKUP(N7, uom!C:C, uom!B:B, "Not Found") | M7: Tube | N7: true | O7: lot | P7: =XLOOKUP(R7, classification!C:C, classification!B:B, "Not Found") | Q7: All
A8: 7 | B8: Digoxin 250mg (x1) | C8: =CONCATENATE("PD", TEXT(A8, "1000000")) | D8: 59 | E8: =XLOOKUP(G8, item_category!C:C, item_category!B:B, "Not Found") | F8: Counting Retail | G8: =XLOOKUP(I8, drug!B:B, drug!A:A, "Not Found") | H8: Digoxin | I8: 1 | J8: =XLOOKUP(L8, uom!C:C, uom!B:B, "Not Found") | K8: Unit(s) | L8: =XLOOKUP(N8, uom!C:C, uom!B:B, "Not Found") | M8: Unit(s) | N8: false | O8: none | P8: =XLOOKUP(R8, classification!C:C, classification!B:B, "Not Found") | Q8: All
A9: 8 | B9: Conference Chair | C9: =CONCATENATE("PD", TEXT(A9, "1000000")) | D9: 8 | E9: =XLOOKUP(G9, item_category!C:C, item_category!B:B, "Not Found") | F9: Office Furniture | G9: =XLOOKUP(I9, drug!B:B, drug!A:A, "Not Found") | H9: Conference Chair | I9: 16.5 | J9: =XLOOKUP(L9, uom!C:C, uom!B:B, "Not Found") | K9: Unit(s) | L9: =XLOOKUP(N9, uom!C:C, uom!B:B, "Not Found") | M9: Unit(s) | N9: false | O9: none | P9: =XLOOKUP(R9, classification!C:C, classification!B:B, "Not Found") | Q9: All
A10: 9 | B10: Office Chair Black | C10: =CONCATENATE("PD", TEXT(A10, "1000000")) | D10: 8 | E10: =XLOOKUP(G10, item_category!C:C, item_category!B:B, "Not Found") | F10: Office Furniture | G10: =XLOOKUP(I10, drug!B:B, drug!A:A, "Not Found") | H10: Office Chair Black | I10: 12.5 | J10: =XLOOKUP(L10, uom!C:C, uom!B:B, "Not Found") | K10: Unit(s) | L10: =XLOOKUP(N10, uom!C:C, uom!B:B, "Not Found") | M10: Unit(s) | N10: false | O10: none | P10: =XLOOKUP(R10, classification!C:C, classification!B:B, "Not Found") | Q10: All
A11: 10 | B11: Corner Desk Black | C11: =CONCATENATE("PD", TEXT(A11, "1000000")) | D11: 8 | E11: =XLOOKUP(G11, item_category!C:C, item_category!B:B, "Not Found") | F11: Office Furniture | G11: =XLOOKUP(I11, drug!B:B, drug!A:A, "Not Found") | H11: Corner Desk Black | I11: 85 | J11: =XLOOKUP(L11, uom!C:C, uom!B:B, "Not Found") | K11: Unit(s) | L11: =XLOOKUP(N11, uom!C:C, uom!B:B, "Not Found") | M11: Unit(s) | N11: false | O11: none | P11: =XLOOKUP(R11, classification!C:C, classification!B:B, "Not Found") | Q11: All
A12: 11 | B12: Drawer Black | C12: =CONCATENATE("PD", TEXT(A12, "1000000")) | D12: 8 | E12: =XLOOKUP(G12, item_category!C:C, item_category!B:B, "Not Found") | F12: Office Furniture | G12: =XLOOKUP(I12, drug!B:B, drug!A:A, "Not Found") | H12: Drawer | I12: 25 | J12: =XLOOKUP(L12, uom!C:C, uom!B:B, "Not Found") | K12: Unit(s) | L12: =XLOOKUP(N12, uom!C:C, uom!B:B, "Not Found") | M12: Unit(s) | N12: false | O12: none | P12: =XLOOKUP(R12, classification!C:C, classification!B:B, "Not Found") | Q12: All
A13: 12 | B13: Desk Stand with Screen | C13: =CONCATENATE("PD", TEXT(A13, "1000000")) | D13: 8 | E13: =XLOOKUP(G13, item_category!C:C, item_category!B:B, "Not Found") | F13: Office Furniture | G13: =XLOOKUP(I13, drug!B:B, drug!A:A, "Not Found") | H13: Desk Stand With | I13: 2100 | J13: =XLOOKUP(L13, uom!C:C, uom!B:B, "Not Found") | K13: Unit(s) | L13: =XLOOKUP(N13, uom!C:C, uom!B:B, "Not Found") | M13: Unit(s) | N13: false | O13: none | P13: =XLOOKUP(R13, classification!C:C, classification!B:B, "Not Found") | Q13: All
... A678: 677 | B678: Locid Suspension | C678: =CONCATENATE("PD", TEXT(A678, "1000000")) | D678: 67 | E678: =XLOOKUP(G678, item_category!C:C, item_category!B:B, "Not Found") | F678: OTC Liquids | G678: =XLOOKUP(I678, drug!B:B, drug!A:A, "Not Found") | H678: Locid | I678: 1 | J678: =XLOOKUP(L678, uom!C:C, uom!B:B, "Not Found") | K678: Unit(s) | L678: =XLOOKUP(N678, uom!C:C, uom!B:B, "Not Found") | M678: Unit(s) | N678: false | O678: none | P678: =XLOOKUP(R678, classification!C:C, classification!B:B, "Not Found") | Q678: All
A679: 678 | B679: Magsil Syrup 100ml | C679: =CONCATENATE("PD", TEXT(A679, "1000000")) | D679: 67 | E679: =XLOOKUP(G679, item_category!C:C, item_category!B:B, "Not Found") | F679: OTC Liquids | G679: =XLOOKUP(I679, drug!B:B, drug!A:A, "Not Found") | I679: 1 | J679: =XLOOKUP(L679, uom!C:C, uom!B:B, "Not Found") | K679: Unit(s) | L679: =XLOOKUP(N679, uom!C:C, uom!B:B, "Not Found") | M679: Unit(s) | N679: false | O679: none | P679: =XLOOKUP(R679, classification!C:C, classification!B:B, "Not Found") | Q679: All
A680: 679 | B680: Magsil Syrup 190ml | C680: =CONCATENATE("PD", TEXT(A680, "1000000")) | D680: 67 | E680: =XLOOKUP(G680, item_category!C:C, item_category!B:B, "Not Found") | F680: OTC Liquids | G680: =XLOOKUP(I680, drug!B:B, drug!A:A, "Not Found") | I680: 1 | J680: =XLOOKUP(L680, uom!C:C, uom!B:B, "Not Found") | K680: Unit(s) | L680: =XLOOKUP(N680, uom!C:C, uom!B:B, "Not Found") | M680: Unit(s) | N680: false | O680: none | P680: =XLOOKUP(R680, classification!C:C, classification!B:B, "Not Found") | Q680: All
A681: 680 | B681: Megacid Suspension | C681: =CONCATENATE("PD", TEXT(A681, "1000000")) | D681: 67 | E681: =XLOOKUP(G681, item_category!C:C, item_category!B:B, "Not Found") | F681: OTC Liquids | G681: =XLOOKUP(I681, drug!B:B, drug!A:A, "Not Found") | I681: 1 | J681: =XLOOKUP(L681, uom!C:C, uom!B:B, "Not Found") | K681: Unit(s) | L681: =XLOOKUP(N681, uom!C:C, uom!B:B, "Not Found") | M681: Unit(s) | N681: false | O681: none | P681: =XLOOKUP(R681, classification!C:C, classification!B:B, "Not Found") | Q681: All
A682: 681 | B682: peptomag usp 200ml | C682: =CONCATENATE("PD", TEXT(A682, "1000000")) | D682: 67 | E682: =XLOOKUP(G682, item_category!C:C, item_category!B:B, "Not Found") | F682: OTC Liquids | G682: =XLOOKUP(I682, drug!B:B, drug!A:A, "Not Found") | I682: 1 | J682: =XLOOKUP(L682, uom!C:C, uom!B:B, "Not Found") | K682: Unit(s) | L682: =XLOOKUP(N682, uom!C:C, uom!B:B, "Not Found") | M682: Unit(s) | N682: false | O682: none | P682: =XLOOKUP(R682, classification!C:C, classification!B:B, "Not Found") | Q682: All
A683: 682 | B683: polycil antacid suspension | C683: =CONCATENATE("PD", TEXT(A683, "1000000")) | D683: 67 | E683: =XLOOKUP(G683, item_category!C:C, item_category!B:B, "Not Found") | F683: OTC Liquids | G683: =XLOOKUP(I683, drug!B:B, drug!A:A, "Not Found") | I683: 1 | J683: =XLOOKUP(L683, uom!C:C, uom!B:B, "Not Found") | K683: Unit(s) | L683: =XLOOKUP(N683, uom!C:C, uom!B:B, "Not Found") | M683: Unit(s) | N683: false | O683: none | P683: =XLOOKUP(R683, classification!C:C, classification!B:B, "Not Found") | Q683: All
A684: 683 | B684: Polycrol Gel | C684: =CONCATENATE("PD", TEXT(A684, "1000000")) | D684: 67 | E684: =XLOOKUP(G684, item_category!C:C, item_category!B:B, "Not Found") | F684: OTC Liquids | G684: =XLOOKUP(I684, drug!B:B, drug!A:A, "Not Found") | I684: 1 | J684: =XLOOKUP(L684, uom!C:C, uom!B:B, "Not Found") | K684: Unit(s) | L684: =XLOOKUP(N684, uom!C:C, uom!B:B, "Not Found") | M684: Unit(s) | N684: false | O684: none | P684: =XLOOKUP(R684, classification!C:C, classification!B:B, "Not Found") | Q684: All
A685: 684 | B685: Polyfort Suspension | C685: =CONCATENATE("PD", TEXT(A685, "1000000")) | D685: 67 | E685: =XLOOKUP(G685, item_category!C:C, item_category!B:B, "Not Found") | F685: OTC Liquids | G685: =XLOOKUP(I685, drug!B:B, drug!A:A, "Not Found") | H685: Polyfort | I685: 1 | J685: =XLOOKUP(L685, uom!C:C, uom!B:B, "Not Found") | K685: Unit(s) | L685: =XLOOKUP(N685, uom!C:C, uom!B:B, "Not Found") | M685: Unit(s) | N685: false | O685: none | P685: =XLOOKUP(R685, classification!C:C, classification!B:B, "Not Found") | Q685: All
A686: 685 | B686: Recler Gel | C686: =CONCATENATE("PD", TEXT(A686, "1000000")) | D686: 67 | E686: =XLOOKUP(G686, item_category!C:C, item_category!B:B, "Not Found") | F686: OTC Liquids | G686: =XLOOKUP(I686, drug!B:B, drug!A:A, "Not Found") | I686: 1 | J686: =XLOOKUP(L686, uom!C:C, uom!B:B, "Not Found") | K686: Unit(s) | L686: =XLOOKUP(N686, uom!C:C, uom!B:B, "Not Found") | M686: Unit(s) | N686: false | O686: none | P686: =XLOOKUP(R686, classification!C:C, classification!B:B, "Not Found") | Q686: All
A687: 686 | B687: Relcer gel Antacid susp | C687: =CONCATENATE("PD", TEXT(A687, "1000000")) | D687: 67 | E687: =XLOOKUP(G687, item_category!C:C, item_category!B:B, "Not Found") | F687: OTC Liquids | G687: =XLOOKUP(I687, drug!B:B, drug!A:A, "Not Found") | I687: 1 | J687: =XLOOKUP(L687, uom!C:C, uom!B:B, "Not Found") | K687: Unit(s) | L687: =XLOOKUP(N687, uom!C:C, uom!B:B, "Not Found") | M687: Unit(s) | N687: false | O687: none | P687: =XLOOKUP(R687, classification!C:C, classification!B:B, "Not Found") | Q687: All
A688: 687 | B688: Rulox Suspension | C688: =CONCATENATE("PD", TEXT(A688, "1000000")) | D688: 67 | E688: =XLOOKUP(G688, item_category!C:C, item_category!B:B, "Not Found") | F688: OTC Liquids | G688: =XLOOKUP(I688, drug!B:B, drug!A:A, "Not Found") | I688: 1 | J688: =XLOOKUP(L688, uom!C:C, uom!B:B, "Not Found") | K688: Unit(s) | L688: =XLOOKUP(N688, uom!C:C, uom!B:B, "Not Found") | M688: Unit(s) | N688: false | O688: none | P688: =XLOOKUP(R688, classification!C:C, classification!B:B, "Not Found") | Q688: All
A689: 688 | B689: De - Shalom Anti Diarrhoea | C689: =CONCATENATE("PD", TEXT(A689, "1000000")) | D689: 67 | E689: =XLOOKUP(G689, item_category!C:C, item_category!B:B, "Not Found") | F689: OTC Liquids | G689: =XLOOKUP(I689, drug!B:B, drug!A:A, "Not Found") | I689: 1 | J689: =XLOOKUP(L689, uom!C:C, uom!B:B, "Not Found") | K689: Unit(s) | L689: =XLOOKUP(N689, uom!C:C, uom!B:B, "Not Found") | M689: Unit(s) | N689: false | O689: none | P689: =XLOOKUP(R689, classification!C:C, classification!B:B, "Not Found") | Q689: All
A690: 689 | B690: Benzyl Benzoate 100ml | C690: =CONCATENATE("PD", TEXT(A690, "1000000")) | D690: 67 | E690: =XLOOKUP(G690, item_category!C:C, item_category!B:B, "Not Found") | F690: OTC Liquids | G690: =XLOOKUP(I690, drug!B:B, drug!A:A, "Not Found") | H690: Benzyl benzoate | I690: 1 | J690: =XLOOKUP(L690, uom!C:C, uom!B:B, "Not Found") | K690: Unit(s) | L690: =XLOOKUP(N690, uom!C:C, uom!B:B, "Not Found") | M690: Unit(s) | N690: false | O690: none | P690: =XLOOKUP(R690, classification!C:C, classification!B:B, "Not Found") | Q690: All
A691: 690 | B691: Bromex Syrup | C691: =CONCATENATE("PD", TEXT(A691, "1000000")) | D691: 67 | E691: =XLOOKUP(G691, item_category!C:C, item_category!B:B, "Not Found") | F691: OTC Liquids | G691: =XLOOKUP(I691, drug!B:B, drug!A:A, "Not Found") | I691: 1 | J691: =XLOOKUP(L691, uom!C:C, uom!B:B, "Not Found") | K691: Unit(s) | L691: =XLOOKUP(N691, uom!C:C, uom!B:B, "Not Found") | M691: Unit(s) | N691: false | O691: none | P691: =XLOOKUP(R691, classification!C:C, classification!B:B, "Not Found") | Q691: All
A692: 691 | B692: cefamor Syrup 250mg | C692: =CONCATENATE("PD", TEXT(A692, "1000000")) | D692: 67 | E692: =XLOOKUP(G692, item_category!C:C, item_category!B:B, "Not Found") | F692: OTC Liquids | G692: =XLOOKUP(I692, drug!B:B, drug!A:A, "Not Found") | I692: 1 | J692: =XLOOKUP(L692, uom!C:C, uom!B:B, "Not Found") | K692: Unit(s) | L692: =XLOOKUP(N692, uom!C:C, uom!B:B, "Not Found") | M692: Unit(s) | N692: false | O692: none | P692: =XLOOKUP(R692, classification!C:C, classification!B:B, "Not Found") | Q692: All
A693: 692 | B693: Fivarex Syrup | C693: =CONCATENATE("PD", TEXT(A693, "1000000")) | D693: 67 | E693: =XLOOKUP(G693, item_category!C:C, item_category!B:B, "Not Found") | F693: OTC Liquids | G693: =XLOOKUP(I693, drug!B:B, drug!A:A, "Not Found") | I693: 1 | J693: =XLOOKUP(L693, uom!C:C, uom!B:B, "Not Found") | K693: Unit(s) | L693: =XLOOKUP(N693, uom!C:C, uom!B:B, "Not Found") | M693: Unit(s) | N693: false | O693: none | P693: =XLOOKUP(R693, classification!C:C, classification!B:B, "Not Found") | Q693: All
A694: 693 | B694: Moko Benzyl Benzoate 100ml | C694: =CONCATENATE("PD", TEXT(A694, "1000000")) | D694: 67 | E694: =XLOOKUP(G694, item_category!C:C, item_category!B:B, "Not Found") | F694: OTC Liquids | G694: =XLOOKUP(I694, drug!B:B, drug!A:A, "Not Found") | H694: Benzyl benzoate | I694: 1 | J694: =XLOOKUP(L694, uom!C:C, uom!B:B, "Not Found") | K694: Unit(s) | L694: =XLOOKUP(N694, uom!C:C, uom!B:B, "Not Found") | M694: Unit(s) | N694: false | O694: none | P694: =XLOOKUP(R694, classification!C:C, classification!B:B, "Not Found") | Q694: All
A695: 694 | B695: Moko quinine syr | C695: =CONCATENATE("PD", TEXT(A695, "1000000")) | D695: 67 | E695: =XLOOKUP(G695, item_category!C:C, item_category!B:B, "Not Found") | F695: OTC Liquids | G695: =XLOOKUP(I695, drug!B:B, drug!A:A, "Not Found") | H695: Quinine | I695: 1 | J695: =XLOOKUP(L695, uom!C:C, uom!B:B, "Not Found") | K695: Unit(s) | L695: =XLOOKUP(N695, uom!C:C, uom!B:B, "Not Found") | M695: Unit(s) | N695: false | O695: none | P695: =XLOOKUP(R695, classification!C:C, classification!B:B, "Not Found") | Q695: All
A696: 695 | B696: Daily Living Bitters | C696: =CONCATENATE("PD", TEXT(A696, "1000000")) | D696: 67 | E696: =XLOOKUP(G696, item_category!C:C, item_category!B:B, "Not Found") | F696: OTC Liquids | G696: =XLOOKUP(I696, drug!B:B, drug!A:A, "Not Found") | I696: 1 | J696: =XLOOKUP(L696, uom!C:C, uom!B:B, "Not Found") | K696: Unit(s) | L696: =XLOOKUP(N696, uom!C:C, uom!B:B, "Not Found") | M696: Unit(s) | N696: false | O696: none | P696: =XLOOKUP(R696, classification!C:C, classification!B:B, "Not Found") | Q696: All
A697: 696 | B697: Jawasil Suspension 100ml | C697: =CONCATENATE("PD", TEXT(A697, "1000000")) | D697: 67 | E697: =XLOOKUP(G697, item_category!C:C, item_category!B:B, "Not Found") | F697: OTC Liquids | G697: =XLOOKUP(I697, drug!B:B, drug!A:A, "Not Found") | I697: 600 | J697: =XLOOKUP(L697, uom!C:C, uom!B:B, "Not Found") | K697: Suspension Bottle | L697: =XLOOKUP(N697, uom!C:C, uom!B:B, "Not Found") | M697: Suspension Bottle | N697: true | O697: lot | P697: =XLOOKUP(R697, classification!C:C, classification!B:B, "Not Found") | Q697: All
A698: 697 | B698: Gestid Suspension 100ml | C698: =CONCATENATE("PD", TEXT(A698, "1000000")) | D698: 67 | E698: =XLOOKUP(G698, item_category!C:C, item_category!B:B, "Not Found") | F698: OTC Liquids | G698: =XLOOKUP(I698, drug!B:B, drug!A:A, "Not Found") | H698: Gestid | I698: 500 | J698: =XLOOKUP(L698, uom!C:C, uom!B:B, "Not Found") | K698: Syrup Bottle | L698: =XLOOKUP(N698, uom!C:C, uom!B:B, "Not Found") | M698: Syrup Bottle | N698: true | O698: lot | P698: =XLOOKUP(R698, classification!C:C, classification!B:B, "Not Found") | Q698: All
A699: 698 | B699: Evans Swedish Bitters | C699: =CONCATENATE("PD", TEXT(A699, "1000000")) | D699: 67 | E699: =XLOOKUP(G699, item_category!C:C, item_category!B:B, "Not Found") | F699: OTC Liquids | G699: =XLOOKUP(I699, drug!B:B, drug!A:A, "Not Found") | I699: 1 | J699: =XLOOKUP(L699, uom!C:C, uom!B:B, "Not Found") | K699: Unit(s) | L699: =XLOOKUP(N699, uom!C:C, uom!B:B, "Not Found") | M699: Unit(s) | N699: false | O699: none | P699: =XLOOKUP(R699, classification!C:C, classification!B:B, "Not Found") | Q699: All
A700: 699 | B700: Swedish Bitters (Imported) | C700: =CONCATENATE("PD", TEXT(A700, "1000000")) | D700: 67 | E700: =XLOOKUP(G700, item_category!C:C, item_category!B:B, "Not Found") | F700: OTC Liquids | G700: =XLOOKUP(I700, drug!B:B, drug!A:A, "Not Found") | I700: 1 | J700: =XLOOKUP(L700, uom!C:C, uom!B:B, "Not Found") | K700: Unit(s) | L700: =XLOOKUP(N700, uom!C:C, uom!B:B, "Not Found") | M700: Unit(s) | N700: false | O700: none | P700: =XLOOKUP(R700, classification!C:C, classification!B:B, "Not Found") | Q700: All
A701: 700 | B701: Amciron Tonic | C701: =CONCATENATE("PD", TEXT(A701, "1000000")) | D701: 67 | E701: =XLOOKUP(G701, item_category!C:C, item_category!B:B, "Not Found") | F701: OTC Liquids | G701: =XLOOKUP(I701, drug!B:B, drug!A:A, "Not Found") | I701: 1 | J701: =XLOOKUP(L701, uom!C:C, uom!B:B, "Not Found") | K701: Unit(s) | L701: =XLOOKUP(N701, uom!C:C, uom!B:B, "Not Found") | M701: Unit(s) | N701: false | O701: none | P701: =XLOOKUP(R701, classification!C:C, classification!B:B, "Not Found") | Q701: All
A702: 701 | B702: Astymin Tonic 110ml | C702: =CONCATENATE("PD", TEXT(A702, "1000000")) | D702: 67 | E702: =XLOOKUP(G702, item_category!C:C, item_category!B:B, "Not Found") | F702: OTC Liquids | G702: =XLOOKUP(I702, drug!B:B, drug!A:A, "Not Found") | I702: 1 | J702: =XLOOKUP(L702, uom!C:C, uom!B:B, "Not Found") | K702: Unit(s) | L702: =XLOOKUP(N702, uom!C:C, uom!B:B, "Not Found") | M702: Unit(s) | N702: false | O702: none | P702: =XLOOKUP(R702, classification!C:C, classification!B:B, "Not Found") | Q702: All
A703: 702 | B703: Bentonic Tonic | C703: =CONCATENATE("PD", TEXT(A703, "1000000")) | D703: 67 | E703: =XLOOKUP(G703, item_category!C:C, item_category!B:B, "Not Found") | F703: OTC Liquids | G703: =XLOOKUP(I703, drug!B:B, drug!A:A, "Not Found") | I703: 1 | J703: =XLOOKUP(L703, uom!C:C, uom!B:B, "Not Found") | K703: Unit(s) | L703: =XLOOKUP(N703, uom!C:C, uom!B:B, "Not Found") | M703: Unit(s) | N703: false | O703: none | P703: =XLOOKUP(R703, classification!C:C, classification!B:B, "Not Found") | Q703: All
A704: 703 | B704: Biotonic Plus Bood Tonic 200ml | C704: =CONCATENATE("PD", TEXT(A704, "1000000")) | D704: 67 | E704: =XLOOKUP(G704, item_category!C:C, item_category!B:B, "Not Found") | F704: OTC Liquids | G704: =XLOOKUP(I704, drug!B:B, drug!A:A, "Not Found") | I704: 1 | J704: =XLOOKUP(L704, uom!C:C, uom!B:B, "Not Found") | K704: Unit(s) | L704: =XLOOKUP(N704, uom!C:C, uom!B:B, "Not Found") | M704: Unit(s) | N704: false | O704: none | P704: =XLOOKUP(R704, classification!C:C, classification!B:B, "Not Found") | Q704: All
...

Sheet drug
A1: code | B1: name | C1: genericClass | D1: pharmaceuticalClass | E1: generalUse | F1: adultDosage | G1: pediatricDosage | H1: appendixDosages | I1: pharmaceuticsCode | J1: drugComponentNames | K1: pharmaceuticsNames | L1: pharmaceuticsDrugClasses | M1: drugComponents | N1: uuid | O1: sync_status | P1: sync_message | Q1: sync_time
A2: GN-00001 | B2: Abacavir | C2: Anti-Infective Medicines | D2: Nucleoside + nucleotide reverse transcriptase inhibitors | E2: Listed in the Nigeria Essential Medicines List (NDF/EDL) for condition-specific treatment. | F2: Use strength- and indication-specific dosing as provided in the Nigeria Drug Formulary. | G2: Use age/weight-based dosing according to the Nigeria Drug Formulary and pediatric guidance. | I2: =XLOOKUP(K2, pharmaceutical_index!B:B, pharmaceutical_index!A:A, "Not Found") | J2: Abacavir | K2: Abacavir | L2: Nucleoside + nucleotide reverse transcriptase inhibitors | M2: Abacavir
A3: GN-00002 | B3: Abacavir + Efavirenz + Lamivudine | C3: Unclassified | D3: General | E3: Listed in the Nigeria Essential Medicines List (NDF/EDL) for condition-specific treatment. | F3: Use strength- and indication-specific dosing as provided in the Nigeria Drug Formulary. | G3: Use age/weight-based dosing according to the Nigeria Drug Formulary and pediatric guidance. | I3: =XLOOKUP(K3, pharmaceutical_index!B:B, pharmaceutical_index!A:A, "Not Found") | J3: Abacavir,Efavirenz,Lamivudine | K3: Abacavir + Efavirenz + Lamivudine | L3: General | M3: Abacavir, Efavirenz, Lamivudine
A4: GN-00003 | B4: Abacavir + Lamivudine | C4: Anti-Infective Medicines | D4: Fixed-dose combinations (adult First line) | E4: Listed in the Nigeria Essential Medicines List (NDF/EDL) for condition-specific treatment. | F4: Use strength- and indication-specific dosing as provided in the Nigeria Drug Formulary. | G4: Use age/weight-based dosing according to the Nigeria Drug Formulary and pediatric guidance. | I4: =XLOOKUP(K4, pharmaceutical_index!B:B, pharmaceutical_index!A:A, "Not Found") | J4: Abacavir,Lamivudine | K4: Abacavir + Lamivudine | L4: Fixed-dose combinations (adult First line) | M4: Abacavir, Lamivudine
A5: GN-00004 | B5: Abiraterone | C5: Antineoplastic, Immunosuppressive Medicines And Adjuvants | D5: General | E5: Listed in the Nigeria Essential Medicines List (NDF/EDL) for condition-specific treatment. | F5: Use strength- and indication-specific dosing as provided in the Nigeria Drug Formulary. | G5: Use age/weight-based dosing according to the Nigeria Drug Formulary and pediatric guidance. | I5: =XLOOKUP(K5, pharmaceutical_index!B:B, pharmaceutical_index!A:A, "Not Found") | J5: Abiraterone | K5: Abiraterone | L5: General | M5: Abiraterone
A6: GN-00005 | B6: Acetic acid | C6: Medicines For Ear, Nose And Throat | D6: General | E6: Listed in the Nigeria Essential Medicines List (NDF/EDL) for condition-specific treatment. | F6: Use strength- and indication-specific dosing as provided in the Nigeria Drug Formulary. | G6: Use age/weight-based dosing according to the Nigeria Drug Formulary and pediatric guidance. | I6: =XLOOKUP(K6, pharmaceutical_index!B:B, pharmaceutical_index!A:A, "Not Found") | J6: Acetic acid | K6: Acetic acid | L6: General | M6: Acetic acid
A7: GN-00006 | B7: Acetylcysteine | C7: Antidotes And Other Substances Used In Poisonings | D7: Specific | E7: Listed in the Nigeria Essential Medicines List (NDF/EDL) for condition-specific treatment. | F7: Use strength- and indication-specific dosing as provided in the Nigeria Drug Formulary. | G7: Use age/weight-based dosing according to the Nigeria Drug Formulary and pediatric guidance. | I7: =XLOOKUP(K7, pharmaceutical_index!B:B, pharmaceutical_index!A:A, "Not Found") | J7: Acetylcysteine | K7: Acetylcysteine | L7: Specific | M7: Acetylcysteine
A8: GN-00007 | B8: Acetylsalicylic acid | C8: Cardiovascular Medicines | D8: Anti-platelet medicines | E8: Listed in the Nigeria Essential Medicines List (NDF/EDL) for condition-specific treatment. | F8: Use strength- and indication-specific dosing as provided in the Nigeria Drug Formulary. | G8: Use age/weight-based dosing according to the Nigeria Drug Formulary and pediatric guidance. | I8: =XLOOKUP(K8, pharmaceutical_index!B:B, pharmaceutical_index!A:A, "Not Found") | J8: Acetylsalicylic acid | K8: Acetylsalicylic acid | L8: Anti-platelet medicines | M8: Acetylsalicylic acid
A9: GN-00008 | B9: Aciclovir | C9: Anti-Infective Medicines | D9: Antiherpes medicines | E9: Listed in the Nigeria Essential Medicines List (NDF/EDL) for condition-specific treatment. | F9: Use strength- and indication-specific dosing as provided in the Nigeria Drug Formulary. | G9: Use age/weight-based dosing according to the Nigeria Drug Formulary and pediatric guidance. | I9: =XLOOKUP(K9, pharmaceutical_index!B:B, pharmaceutical_index!A:A, "Not Found") | J9: Aciclovir | K9: Aciclovir | L9: Antiherpes medicines | M9: Aciclovir
A10: GN-00009 | B10: Actinomycin-D | C10: Antineoplastic, Immunosuppressive Medicines And Adjuvants | D10: General | E10: Listed in the Nigeria Essential Medicines List (NDF/EDL) for condition-specific treatment. | F10: Use strength- and indication-specific dosing as provided in the Nigeria Drug Formulary. | G10: Use age/weight-based dosing according to the Nigeria Drug Formulary and pediatric guidance. | I10: =XLOOKUP(K10, pharmaceutical_index!B:B, pharmaceutical_index!A:A, "Not Found") | J10: Actinomycin-D | K10: Actinomycin-D | L10: General | M10: Actinomycin-D
A11: GN-00010 | B11: Adalimumab | C11: Antineoplastic, Immunosuppressive Medicines And Adjuvants | D11: General | E11: Listed in the Nigeria Essential Medicines List (NDF/EDL) for condition-specific treatment. | F11: Use strength- and indication-specific dosing as provided in the Nigeria Drug Formulary. | G11: Use age/weight-based dosing according to the Nigeria Drug Formulary and pediatric guidance. | I11: =XLOOKUP(K11, pharmaceutical_index!B:B, pharmaceutical_index!A:A, "Not Found") | J11: Adalimumab | K11: Adalimumab | L11: General | M11: Adalimumab
A12: GN-00011 | B12: Albendazole | C12: Anti-Infective Medicines | D12: Antifilarials | E12: Listed in the Nigeria Essential Medicines List (NDF/EDL) for condition-specific treatment. | F12: Use strength- and indication-specific dosing as provided in the Nigeria Drug Formulary. | G12: Use age/weight-based dosing according to the Nigeria Drug Formulary and pediatric guidance. | I12: =XLOOKUP(K12, pharmaceutical_index!B:B, pharmaceutical_index!A:A, "Not Found") | J12: Albendazole | K12: Albendazole | L12: Antifilarials | M12: Albendazole
A13: GN-00012 | B13: Alfuzosin | C13: Urinary And Erectile Dysfunctions Medicines | D13: General | E13: Listed in the Nigeria Essential Medicines List (NDF/EDL) for condition-specific treatment. | F13: Use strength- and indication-specific dosing as provided in the Nigeria Drug Formulary. | G13: Use age/weight-based dosing according to the Nigeria Drug Formulary and pediatric guidance. | I13: =XLOOKUP(K13, pharmaceutical_index!B:B, pharmaceutical_index!A:A, "Not Found") | J13: Alfuzosin | K13: Alfuzosin | L13: General | M13: Alfuzosin
... A62: GN-00061 | B62: Bicalutamide | C62: Antineoplastic, Immunosuppressive Medicines And Adjuvants | D62: General | E62: Listed in the Nigeria Essential Medicines List (NDF/EDL) for condition-specific treatment. | F62: Use strength- and indication-specific dosing as provided in the Nigeria Drug Formulary. | G62: Use age/weight-based dosing according to the Nigeria Drug Formulary and pediatric guidance. | I62: =XLOOKUP(K62, pharmaceutical_index!B:B, pharmaceutical_index!A:A, "Not Found") | J62: Bicalutamide | K62: Bicalutamide | L62: General | M62: Bicalutamide
A63: GN-00062 | B63: Biotin | C63: Vitamins, Minerals And Nutritionals | D63: General | E63: Listed in the Nigeria Essential Medicines List (NDF/EDL) for condition-specific treatment. | F63: Use strength- and indication-specific dosing as provided in the Nigeria Drug Formulary. | G63: Use age/weight-based dosing according to the Nigeria Drug Formulary and pediatric guidance. | H63: [object Object],[object Object] | I63: =XLOOKUP(K63, pharmaceutical_index!B:B, pharmaceutical_index!A:A, "Not Found") | J63: Biotin | K63: Biotin | L63: General | M63: Biotin
A64: GN-00063 | B64: Biperiden | C64: Medicines For Mental And Behavioural Disorders | D64: Antidotes to antipsychotic medicines | E64: Listed in the Nigeria Essential Medicines List (NDF/EDL) for condition-specific treatment. | F64: Use strength- and indication-specific dosing as provided in the Nigeria Drug Formulary. | G64: Use age/weight-based dosing according to the Nigeria Drug Formulary and pediatric guidance. | I64: =XLOOKUP(K64, pharmaceutical_index!B:B, pharmaceutical_index!A:A, "Not Found") | J64: Biperiden | K64: Biperiden | L64: Antidotes to antipsychotic medicines | M64: Biperiden
A65: GN-00064 | B65: Biphasic isophane insulin | C65: Hormones, Other Endocrine Medicines And Contraceptives | D65: Insulin preparations | E65: Listed in the Nigeria Essential Medicines List (NDF/EDL) for condition-specific treatment. | F65: Use strength- and indication-specific dosing as provided in the Nigeria Drug Formulary. | G65: Use age/weight-based dosing according to the Nigeria Drug Formulary and pediatric guidance. | I65: =XLOOKUP(K65, pharmaceutical_index!B:B, pharmaceutical_index!A:A, "Not Found") | J65: Biphasic isophane insulin | K65: Biphasic isophane insulin | L65: Insulin preparations | M65: Biphasic isophane insulin
A66: GN-00065 | B66: Bleomycin | C66: Antineoplastic, Immunosuppressive Medicines And Adjuvants | D66: General | E66: Listed in the Nigeria Essential Medicines List (NDF/EDL) for condition-specific treatment. | F66: Use strength- and indication-specific dosing as provided in the Nigeria Drug Formulary. | G66: Use age/weight-based dosing according to the Nigeria Drug Formulary and pediatric guidance. | I66: =XLOOKUP(K66, pharmaceutical_index!B:B, pharmaceutical_index!A:A, "Not Found") | J66: Bleomycin | K66: Bleomycin | L66: General | M66: Bleomycin
A67: GN-00066 | B67: Bortezomib | C67: Antineoplastic, Immunosuppressive Medicines And Adjuvants | D67: General | E67: Listed in the Nigeria Essential Medicines List (NDF/EDL) for condition-specific treatment. | F67: Use strength- and indication-specific dosing as provided in the Nigeria Drug Formulary. | G67: Use age/weight-based dosing according to the Nigeria Drug Formulary and pediatric guidance. | I67: =XLOOKUP(K67, pharmaceutical_index!B:B, pharmaceutical_index!A:A, "Not Found") | J67: Bortezomib | K67: Bortezomib | L67: General | M67: Bortezomib
A68: GN-00067 | B68: Bromazepam | C68: Medicines For Mental And Behavioural Disorders | D68: Medicines for anxiety disorders | E68: Listed in the Nigeria Essential Medicines List (NDF/EDL) for condition-specific treatment. | F68: Use strength- and indication-specific dosing as provided in the Nigeria Drug Formulary. | G68: Use age/weight-based dosing according to the Nigeria Drug Formulary and pediatric guidance. | I68: =XLOOKUP(K68, pharmaceutical_index!B:B, pharmaceutical_index!A:A, "Not Found") | J68: Bromazepam | K68: Bromazepam | L68: Medicines for anxiety disorders | M68: Bromazepam
A69: GN-00068 | B69: Budesonide | C69: Medicines Acting On The Respiratory Tract | D69: Antiasthmatic medicines | E69: Listed in the Nigeria Essential Medicines List (NDF/EDL) for condition-specific treatment. | F69: Use strength- and indication-specific dosing as provided in the Nigeria Drug Formulary. | G69: Use age/weight-based dosing according to the Nigeria Drug Formulary and pediatric guidance. | I69: =XLOOKUP(K69, pharmaceutical_index!B:B, pharmaceutical_index!A:A, "Not Found") | J69: Budesonide | K69: Budesonide | L69: Antiasthmatic medicines | M69: Budesonide
A70: GN-00069 | B70: Bupivacaine | C70: Anaesthetics, Preoperative Medicines And Medical Gases | D70: Local anaesthetics | E70: Listed in the Nigeria Essential Medicines List (NDF/EDL) for condition-specific treatment. | F70: Use strength- and indication-specific dosing as provided in the Nigeria Drug Formulary. | G70: Use age/weight-based dosing according to the Nigeria Drug Formulary and pediatric guidance. | I70: =XLOOKUP(K70, pharmaceutical_index!B:B, pharmaceutical_index!A:A, "Not Found") | J70: Bupivacaine | K70: Bupivacaine | L70: Local anaesthetics | M70: Bupivacaine
A71: GN-00070 | B71: Buprenorphine | C71: Medicines For Mental And Behavioural Disorders | D71: Medicines used in substance dependence programmes (See Restricted Medicines List) | E71: Listed in the Nigeria Essential Medicines List (NDF/EDL) for condition-specific treatment. | F71: Use strength- and indication-specific dosing as provided in the Nigeria Drug Formulary. | G71: Use age/weight-based dosing according to the Nigeria Drug Formulary and pediatric guidance. | I71: =XLOOKUP(K71, pharmaceutical_index!B:B, pharmaceutical_index!A:A, "Not Found") | J71: Buprenorphine | K71: Buprenorphine | L71: Medicines used in substance dependence programmes (See Restricted Medicines List) | M71: Buprenorphine
A72: GN-00071 | B72: Buserelin | C72: Antineoplastic, Immunosuppressive Medicines And Adjuvants | D72: General | E72: Listed in the Nigeria Essential Medicines List (NDF/EDL) for condition-specific treatment. | F72: Use strength- and indication-specific dosing as provided in the Nigeria Drug Formulary. | G72: Use age/weight-based dosing according to the Nigeria Drug Formulary and pediatric guidance. | I72: =XLOOKUP(K72, pharmaceutical_index!B:B, pharmaceutical_index!A:A, "Not Found") | J72: Buserelin | K72: Buserelin | L72: General | M72: Buserelin
A73: GN-00072 | B73: Busulfan (Busulphan) | C73: Antineoplastic, Immunosuppressive Medicines And Adjuvants | D73: General | E73: Listed in the Nigeria Essential Medicines List (NDF/EDL) for condition-specific treatment. | F73: Use strength- and indication-specific dosing as provided in the Nigeria Drug Formulary. | G73: Use age/weight-based dosing according to the Nigeria Drug Formulary and pediatric guidance. | I73: =XLOOKUP(K73, pharmaceutical_index!B:B, pharmaceutical_index!A:A, "Not Found") | J73: Busulfan | K73: Busulfan (Busulphan) | L73: General | M73: Busulfan
A74: GN-00073 | B74: Calamine | C74: Unclassified | D74: General | E74: Listed in the Nigeria Essential Medicines List (NDF/EDL) for condition-specific treatment. | F74: Use strength- and indication-specific dosing as provided in the Nigeria Drug Formulary. | G74: Use age/weight-based dosing according to the Nigeria Drug Formulary and pediatric guidance. | I74: =XLOOKUP(K74, pharmaceutical_index!B:B, pharmaceutical_index!A:A, "Not Found") | J74: Calamine | K74: Calamine | L74: General | M74: Calamine
A75: GN-00074 | B75: Calamine + Zinc oxide | C75: Dermatologicals | D75: General | E75: Listed in the Nigeria Essential Medicines List (NDF/EDL) for condition-specific treatment. | F75: Use strength- and indication-specific dosing as provided in the Nigeria Drug Formulary. | G75: Use age/weight-based dosing according to the Nigeria Drug Formulary and pediatric guidance. | I75: =XLOOKUP(K75, pharmaceutical_index!B:B, pharmaceutical_index!A:A, "Not Found") | J75: Calamine,Zinc oxide | K75: Calamine + Zinc oxide | L75: General | M75: Calamine, Zinc oxide
... A209: GN-00208 | B209: Fluticasone furoate | C209: Medicines For Ear, Nose And Throat | D209: General | E209: Listed in the Nigeria Essential Medicines List (NDF/EDL) for condition-specific treatment. | F209: Use strength- and indication-specific dosing as provided in the Nigeria Drug Formulary. | G209: Use age/weight-based dosing according to the Nigeria Drug Formulary and pediatric guidance. | I209: =XLOOKUP(K209, pharmaceutical_index!B:B, pharmaceutical_index!A:A, "Not Found") | J209: Fluticasone furoate | K209: Fluticasone furoate | L209: General | M209: Fluticasone furoate
A210: GN-00209 | B210: Folic acid | C210: Medicines Affecting The Blood | D210: Antianaemia medicines (Haematinics) | E210: Listed in the Nigeria Essential Medicines List (NDF/EDL) for condition-specific treatment. | F210: Use strength- and indication-specific dosing as provided in the Nigeria Drug Formulary. | G210: Use age/weight-based dosing according to the Nigeria Drug Formulary and pediatric guidance. | H210: [object Object],[object Object],[object Object],[object Object] | I210: =XLOOKUP(K210, pharmaceutical_index!B:B, pharmaceutical_index!A:A, "Not Found") | J210: Folic acid | K210: Folic acid | L210: Antianaemia medicines (Haematinics) | M210: Folic acid
A211: GN-00210 | B211: Fomepizole | C211: Antidotes And Other Substances Used In Poisonings | D211: Specific | E211: Listed in the Nigeria Essential Medicines List (NDF/EDL) for condition-specific treatment. | F211: Use strength- and indication-specific dosing as provided in the Nigeria Drug Formulary. | G211: Use age/weight-based dosing according to the Nigeria Drug Formulary and pediatric guidance. | I211: =XLOOKUP(K211, pharmaceutical_index!B:B, pharmaceutical_index!A:A, "Not Found") | J211: Fomepizole | K211: Fomepizole | L211: Specific | M211: Fomepizole
A212: GN-00211 | B212: Formaldehyde | C212: Antiseptics And Disinfectants | D212: General | E212: Listed in the Nigeria Essential Medicines List (NDF/EDL) for condition-specific treatment. | F212: Use strength- and indication-specific dosing as provided in the Nigeria Drug Formulary. | G212: Use age/weight-based dosing according to the Nigeria Drug Formulary and pediatric guidance. | I212: =XLOOKUP(K212, pharmaceutical_index!B:B, pharmaceutical_index!A:A, "Not Found") | J212: Formaldehyde | K212: Formaldehyde | L212: General | M212: Formaldehyde
A213: GN-00212 | B213: Furosemide | C213: Cardiovascular Medicines | D213: Medicines used in heart failure | E213: Listed in the Nigeria Essential Medicines List (NDF/EDL) for condition-specific treatment. | F213: Use strength- and indication-specific dosing as provided in the Nigeria Drug Formulary. | G213: Use age/weight-based dosing according to the Nigeria Drug Formulary and pediatric guidance. | I213: =XLOOKUP(K213, pharmaceutical_index!B:B, pharmaceutical_index!A:A, "Not Found") | J213: Furosemide | K213: Furosemide | L213: Medicines used in heart failure | M213: Furosemide
A214: GN-00213 | B214: Gatifloxacin | C214: Anti-Infective Medicines | D214: Anti-tuberculosis medicines | E214: Listed in the Nigeria Essential Medicines List (NDF/EDL) for condition-specific treatment. | F214: Use strength- and indication-specific dosing as provided in the Nigeria Drug Formulary. | G214: Use age/weight-based dosing according to the Nigeria Drug Formulary and pediatric guidance. | I214: =XLOOKUP(K214, pharmaceutical_index!B:B, pharmaceutical_index!A:A, "Not Found") | J214: Gatifloxacin | K214: Gatifloxacin | L214: Anti-tuberculosis medicines | M214: Gatifloxacin
A215: GN-00214 | B215: Gemcitabine | C215: Antineoplastic, Immunosuppressive Medicines And Adjuvants | D215: General | E215: Listed in the Nigeria Essential Medicines List (NDF/EDL) for condition-specific treatment. | F215: Use strength- and indication-specific dosing as provided in the Nigeria Drug Formulary. | G215: Use age/weight-based dosing according to the Nigeria Drug Formulary and pediatric guidance. | I215: =XLOOKUP(K215, pharmaceutical_index!B:B, pharmaceutical_index!A:A, "Not Found") | J215: Gemcitabine | K215: Gemcitabine | L215: General | M215: Gemcitabine
A216: GN-00215 | B216: Gentamicin | C216: Anti-Infective Medicines | D216: Antibacterial medicines | E216: Listed in the Nigeria Essential Medicines List (NDF/EDL) for condition-specific treatment. | F216: Use strength- and indication-specific dosing as provided in the Nigeria Drug Formulary. | G216: Use age/weight-based dosing according to the Nigeria Drug Formulary and pediatric guidance. | I216: =XLOOKUP(K216, pharmaceutical_index!B:B, pharmaceutical_index!A:A, "Not Found") | J216: Gentamicin | K216: Gentamicin | L216: Antibacterial medicines | M216: Gentamicin
A217: GN-00216 | B217: Gentian violet | C217: Dermatological Medicines | D217: Anti-infective medicines | E217: Listed in the Nigeria Essential Medicines List (NDF/EDL) for condition-specific treatment. | F217: Use strength- and indication-specific dosing as provided in the Nigeria Drug Formulary. | G217: Use age/weight-based dosing according to the Nigeria Drug Formulary and pediatric guidance. | I217: =XLOOKUP(K217, pharmaceutical_index!B:B, pharmaceutical_index!A:A, "Not Found") | J217: Gentian violet | K217: Gentian violet | L217: Anti-infective medicines | M217: Gentian violet
A218: GN-00217 | B218: Glibenclamide | C218: Hormones, Other Endocrine Medicines And Contraceptives | D218: Oral antidiabetic medicines | E218: Listed in the Nigeria Essential Medicines List (NDF/EDL) for condition-specific treatment. | F218: Use strength- and indication-specific dosing as provided in the Nigeria Drug Formulary. | G218: Use age/weight-based dosing according to the Nigeria Drug Formulary and pediatric guidance. | I218: =XLOOKUP(K218, pharmaceutical_index!B:B, pharmaceutical_index!A:A, "Not Found") | J218: Glibenclamide | K218: Glibenclamide | L218: Oral antidiabetic medicines | M218: Glibenclamide
A219: GN-00218 | B219: Gliclazide | C219: Hormones, Other Endocrine Medicines And Contraceptives | D219: Oral antidiabetic medicines | E219: Listed in the Nigeria Essential Medicines List (NDF/EDL) for condition-specific treatment. | F219: Use strength- and indication-specific dosing as provided in the Nigeria Drug Formulary. | G219: Use age/weight-based dosing according to the Nigeria Drug Formulary and pediatric guidance. | I219: =XLOOKUP(K219, pharmaceutical_index!B:B, pharmaceutical_index!A:A, "Not Found") | J219: Gliclazide | K219: Gliclazide | L219: Oral antidiabetic medicines | M219: Gliclazide
A220: GN-00219 | B220: Glimepyride | C220: Unclassified | D220: General | E220: Listed in the Nigeria Essential Medicines List (NDF/EDL) for condition-specific treatment. | F220: Use strength- and indication-specific dosing as provided in the Nigeria Drug Formulary. | G220: Use age/weight-based dosing according to the Nigeria Drug Formulary and pediatric guidance. | I220: =XLOOKUP(K220, pharmaceutical_index!B:B, pharmaceutical_index!A:A, "Not Found") | J220: Glimepyride | K220: Glimepyride | L220: General | M220: Glimepyride
A221: GN-00220 | B221: Glucagon | C221: Hormones, Other Endocrine Medicines And Contraceptives | D221: Medicines for hypoglycaemia | E221: Listed in the Nigeria Essential Medicines List (NDF/EDL) for condition-specific treatment. | F221: Use strength- and indication-specific dosing as provided in the Nigeria Drug Formulary. | G221: Use age/weight-based dosing according to the Nigeria Drug Formulary and pediatric guidance. | I221: =XLOOKUP(K221, pharmaceutical_index!B:B, pharmaceutical_index!A:A, "Not Found") | J221: Glucagon | K221: Glucagon | L221: Medicines for hypoglycaemia | M221: Glucagon
...

Sheet pharmaceutical_index
A1: code | B1: clinicalName | C1: drugClass | D1: pharmacology | E1: indications | F1: contraindications | G1: mechanism | H1: uuid | I1: sync_status | J1: sync_message | K1: sync_time
A2: PN-00001 | B2: Abacavir | C2: Nucleoside + nucleotide reverse transcriptase inhibitors | D2: NDF-listed pharmacologic agent used per formulation and approved indications. | E2: Condition-specific indications as defined in the Nigeria Drug Formulary. | F2: Contraindications include hypersensitivity and condition-specific restrictions in NDF guidance. | G2: Mechanism varies by active ingredient(s); refer to NDF therapeutic guidance for clinical use.
A3: PN-00002 | B3: Abacavir + Efavirenz + Lamivudine | C3: General | D3: NDF-listed pharmacologic agent used per formulation and approved indications. | E3: Condition-specific indications as defined in the Nigeria Drug Formulary. | F3: Contraindications include hypersensitivity and condition-specific restrictions in NDF guidance. | G3: Mechanism varies by active ingredient(s); refer to NDF therapeutic guidance for clinical use.
A4: PN-00003 | B4: Abacavir + Lamivudine | C4: Fixed-dose combinations (adult First line) | D4: NDF-listed pharmacologic agent used per formulation and approved indications. | E4: Condition-specific indications as defined in the Nigeria Drug Formulary. | F4: Contraindications include hypersensitivity and condition-specific restrictions in NDF guidance. | G4: Mechanism varies by active ingredient(s); refer to NDF therapeutic guidance for clinical use.
A5: PN-00004 | B5: Abiraterone | C5: General | D5: NDF-listed pharmacologic agent used per formulation and approved indications. | E5: Condition-specific indications as defined in the Nigeria Drug Formulary. | F5: Contraindications include hypersensitivity and condition-specific restrictions in NDF guidance. | G5: Mechanism varies by active ingredient(s); refer to NDF therapeutic guidance for clinical use.
A6: PN-00005 | B6: Acetic acid | C6: General | D6: NDF-listed pharmacologic agent used per formulation and approved indications. | E6: Condition-specific indications as defined in the Nigeria Drug Formulary. | F6: Contraindications include hypersensitivity and condition-specific restrictions in NDF guidance. | G6: Mechanism varies by active ingredient(s); refer to NDF therapeutic guidance for clinical use.
A7: PN-00006 | B7: Acetylcysteine | C7: Specific | D7: NDF-listed pharmacologic agent used per formulation and approved indications. | E7: Condition-specific indications as defined in the Nigeria Drug Formulary. | F7: Contraindications include hypersensitivity and condition-specific restrictions in NDF guidance. | G7: Mechanism varies by active ingredient(s); refer to NDF therapeutic guidance for clinical use.
A8: PN-00007 | B8: Acetylsalicylic acid | C8: Anti-platelet medicines | D8: NDF-listed pharmacologic agent used per formulation and approved indications. | E8: Condition-specific indications as defined in the Nigeria Drug Formulary. | F8: Contraindications include hypersensitivity and condition-specific restrictions in NDF guidance. | G8: Mechanism varies by active ingredient(s); refer to NDF therapeutic guidance for clinical use.
A9: PN-00008 | B9: Aciclovir | C9: Antiherpes medicines | D9: NDF-listed pharmacologic agent used per formulation and approved indications. | E9: Condition-specific indications as defined in the Nigeria Drug Formulary. | F9: Contraindications include hypersensitivity and condition-specific restrictions in NDF guidance. | G9: Mechanism varies by active ingredient(s); refer to NDF therapeutic guidance for clinical use.
A10: PN-00009 | B10: Actinomycin-D | C10: General | D10: NDF-listed pharmacologic agent used per formulation and approved indications. | E10: Condition-specific indications as defined in the Nigeria Drug Formulary. | F10: Contraindications include hypersensitivity and condition-specific restrictions in NDF guidance. | G10: Mechanism varies by active ingredient(s); refer to NDF therapeutic guidance for clinical use.
A11: PN-00010 | B11: Adalimumab | C11: General | D11: NDF-listed pharmacologic agent used per formulation and approved indications. | E11: Condition-specific indications as defined in the Nigeria Drug Formulary. | F11: Contraindications include hypersensitivity and condition-specific restrictions in NDF guidance. | G11: Mechanism varies by active ingredient(s); refer to NDF therapeutic guidance for clinical use.
A12: PN-00011 | B12: Albendazole | C12: Antifilarials | D12: NDF-listed pharmacologic agent used per formulation and approved indications. | E12: Condition-specific indications as defined in the Nigeria Drug Formulary. | F12: Contraindications include hypersensitivity and condition-specific restrictions in NDF guidance. | G12: Mechanism varies by active ingredient(s); refer to NDF therapeutic guidance for clinical use.
A13: PN-00012 | B13: Alfuzosin | C13: General | D13: NDF-listed pharmacologic agent used per formulation and approved indications. | E13: Condition-specific indications as defined in the Nigeria Drug Formulary. | F13: Contraindications include hypersensitivity and condition-specific restrictions in NDF guidance. | G13: Mechanism varies by active ingredient(s); refer to NDF therapeutic guidance for clinical use.
... A1710: PN-1709 | B1710: Cenpai | C1710: General | D1710: Pharmacology depends on active ingredient and formulation. | E1710: Indications depend on approved label and treatment guideline. | F1710: Contraindications include known hypersensitivity; verify label-specific risks. | G1710: Mechanism varies by active ingredient(s).
B1711: pharmaceutical_index_name
